Workbook

Sheet Instructions
A1: SATRF Score Import — How to use this workbook
A3: Colour key | B3: Blue/peach cells = you type here. Grey cells = calculated automatically (do not edit).
A4: Tabs | B4: Prone 50m · F-Class · 3-Position 50m — one tab per discipline. Use the tab that matches the match.
A5: One row | B5: One row per shooter per match. Add as many rows as you need (formatting extends to row 100).
A6: Members tab | B6: Add/maintain your shooters there. Their names appear in the Shooter dropdown. Guests can be typed freely.
A7: Date | B7: Enter as YYYY-MM-DD (e.g. 2026-05-09). Excel date cells also work.
A8: Dropdowns | B8: Discipline, Shooter, Club, Category and Status are dropdowns. Pick from the list (or free-type a guest).
A9: Prone & F-Class | B9: 6 series × 10 shots. Enter the decimal series total (e.g. 100.7). Integer ring totals are optional.
A10: F-Class note | B10: Scored like ISSF: 2 diagrams of 5 = a 10-shot series, 6 series, total /600. Just enter the series total.
A11: 3-Position | B11: Enter one total per position: Kneeling, Prone, Standing (20 shots each, 60 total). Decimals and/or integers.
A12: Decimal max | B12: Decimal max flags impossible values: 109.0 per 10-shot series (Prone/F-Class); 218.0 per 20-shot 3P position.
A13: Totals | B13: The Total columns are auto-summed for your own sanity check. The website recalculates on import.
A14: Status | B14: official (default) or provisional for incomplete/training scores.
A15: Electronic vs paper | B15: From an electronic PDF: copy each series/position decimal. From paper: enter the hand-tallied totals.

Sheet Workflow
B1: SATRF Scoring Workflow
B2: Top to bottom. GREEN = every match · AMBER = only if a final is held · BLUE = a tab you type in · TEAL = auto result · NAVY = upload
B4: STEP 1 Set up the match → Match Setup tab | I4: One row per match: ID, name, date, discipline. Set 'Final held? Yes/No' and number of finalists. You decide per match — a small field can be qualification-only.
D6: ⬇
B7: STEP 2 (always) Capture Qualification Prone / F-Class / 3-Position tab | I7: Enter series totals (Prone & F-Class: 6×10) or position totals (3P: kneeling / prone / standing). The Check column should read 'OK to upload'.
D9: ⬇
B10: DECISION — was a final held? | I10: Read 'Final held?' from Match Setup. NO → go to Step 4. YES → do Step 3 first.
B12: NO ⬇ | F12: YES ⬇
B13: No final. Everyone ranked by qualification score. Go to Step 4. | E13: STEP 3 Capture the Final → '3P Final' / 'Prone Final' tab | I13: FINAL = decimal elimination: 3+3 opening then single shots. Finalists START AT ZERO — qualification is NOT carried forward. Record the final total + rank per finalist.
C15: ⬇ | F15: ⬇
B16: STEP 4 Build overall result → Results tab | I16: ISSF ranking: finalists by their FINAL result on top, then everyone else by QUALIFICATION. Never added together.
D18: ⬇
B19: STEP 5 Upload to website → Export (Upload) tab | I19: Two-stage upload recommended: qualification file first, then the final as a separate linked record. Fallback: one file filtered by the 'Stage' column.
B22: KEY ISSF RULE — Qualification and Final are SEPARATE stages. Finalists start at zero; the qualification score is not carried into the final. Overall placing = finalists by final result, then non-finalists by qualification. The two scores are never summed.
B26: Legend
D27: Always do — every match
D28: Only when a final is held
D29: A tab you type data into
D30: Auto-assembled result
D31: Upload step

Sheet Dashboard
A1: Score Summary Dashboard
A2: Auto-updates as you enter scores. Read-only.
A4: Discipline | B4: Entries | C4: Ready to upload | D4: Top Total (dec) | E4: Avg Total (dec)
A5: Prone 50m | B5: =COUNTIF('Prone 50m'!$D$2:$D$101,"<>") -> 2 | C5: =COUNTIF('Prone 50m'!$Y$2:$Y$101,"OK to upload") -> 2 | D5: =IFERROR(MAX('Prone 50m'!$S$2:$S$101),0) -> 600.4 | E5: =IFERROR(AVERAGE('Prone 50m'!$S$2:$S$101),0) -> 596.85
A6: F-Class | B6: =COUNTIF('F-Class'!$D$2:$D$101,"<>") -> 1 | C6: =COUNTIF('F-Class'!$Y$2:$Y$101,"OK to upload") -> 1 | D6: =IFERROR(MAX('F-Class'!$S$2:$S$101),0) -> 591 | E6: =IFERROR(AVERAGE('F-Class'!$S$2:$S$101),0) -> 591
A7: 3-Position 50m | B7: =COUNTIF('3-Position 50m'!$D$2:$D$101,"<>") -> 2 | C7: =COUNTIF('3-Position 50m'!$S$2:$S$101,"OK to upload") -> 0 | D7: =IFERROR(MAX('3-Position 50m'!$M$2:$M$101),0) -> 626.9 | E7: =IFERROR(AVERAGE('3-Position 50m'!$M$2:$M$101),0) -> 626.9
A8: TOTAL | B8: =SUM(B5:B7) -> 5 | C8: =SUM(C5:C7) -> 3
A10: Entries by Category (all disciplines)
A11: Category | B11: Count
A12: open | B12: =COUNTIF('Prone 50m'!$F$2:$F$101,"open")+COUNTIF('F-Class'!$F$2:$F$101,"open")+COUNTIF('3-Position 50m'!$F$2:$F$101,"open") -> 2
A13: junior | B13: =COUNTIF('Prone 50m'!$F$2:$F$101,"junior")+COUNTIF('F-Class'!$F$2:$F$101,"junior")+COUNTIF('3-Position 50m'!$F$2:$F$101,"junior") -> 1
A14: veteran | B14: =COUNTIF('Prone 50m'!$F$2:$F$101,"veteran")+COUNTIF('F-Class'!$F$2:$F$101,"veteran")+COUNTIF('3-Position 50m'!$F$2:$F$101,"veteran") -> 0
A15: ladies | B15: =COUNTIF('Prone 50m'!$F$2:$F$101,"ladies")+COUNTIF('F-Class'!$F$2:$F$101,"ladies")+COUNTIF('3-Position 50m'!$F$2:$F$101,"ladies") -> 1

Sheet Match Setup
A1: Match Setup — define each match once
A2: Fill one row per match. The Finals and Results tabs read from here. 'Final held?' decides whether a final is run; 'Finalists' sets how many advance (adjustable per match).
A4: Match ID | B4: Match Name | C4: Date | D4: Discipline | E4: Final held? | F4: Finalists | G4: Notes
A5: M001 | B5: May Club Prone | C5: 2026-05-09 | D5: prone_50m | E5: No | F5: 8 | G5: Qualification only — small field
A6: M002 | B6: Open 3P Champs | C6: 2026-05-23 | D6: three_position_50m | E6: Yes | F6: 6 | G6: Final held — record result (total + rank) on Finals tab

Sheet Prone 50m
A1: Date (YYYY-MM-DD) | B1: Event Name | C1: Discipline | D1: Shooter Name | E1: Club | F1: Category | G1: S1 Dec | H1: S2 Dec | I1: S3 Dec | J1: S4 Dec | K1: S5 Dec | L1: S6 Dec | M1: S1 Int | N1: S2 Int | O1: S3 Int | P1: S4 Int | Q1: S5 Int | R1: S6 Int | S1: Total Dec | T1: Total Int | U1: Status | V1: Notes | Y1: Check
A2: 2026-05-09 | B2: 50 Meter Rifle Prone | C2: prone_50m | D2: Arnold Prone | E2: =IFERROR(IF(D2="","",VLOOKUP(D2,Members!$A$2:$C$16,2,FALSE())),"") -> Modderbee | F2: =IFERROR(IF(D2="","",VLOOKUP(D2,Members!$A$2:$C$16,3,FALSE())),"") -> open | G2: 100.7 | H2: 101.6 | I2: 97.4 | J2: 100.7 | K2: 99.3 | L2: 100.7 | M2: 95 | N2: 95 | O2: 93 | P2: 95 | Q2: 94 | R2: 95 | S2: =IF(COUNT(G2:L2)=0,"",SUM(G2:L2)) -> 600.4 | T2: =IF(COUNT(M2:R2)=0,"",SUM(M2:R2)) -> 567 | U2: official | V2: Example from electronic target — 60-shot match | Y2: =IF(AND(A2="",B2="",D2="",COUNT(G2:L2)=0),"",IF(D2="","Missing shooter",IF(A2="","Missing date",IF(B2="","Missing event",IF(E2="","Club not in roster (type manually)",IF(COUNT(G2:L2)=0,"No scores entered",IF(U2="","Set status (official/provisional)",IF(COUNTIFS($A$2:$A$101,A2,$B$2:$B$101,B2,$D$2:$D$101,D2)>1,"Duplicate entry","OK to upload")))))))) -> OK to upload
A3: 2026-06-10 | B3: SATRF Nationals | C3: prone_50m | D3: Jane Member | E3: =IFERROR(IF(D3="","",VLOOKUP(D3,Members!$A$2:$C$16,2,FALSE())),"") -> SATRF Club | F3: =IFERROR(IF(D3="","",VLOOKUP(D3,Members!$A$2:$C$16,3,FALSE())),"") -> ladies | G3: 98.5 | H3: 99.1 | I3: 97.8 | J3: 100.2 | K3: 99 | L3: 98.7 | S3: =IF(COUNT(G3:L3)=0,"",SUM(G3:L3)) -> 593.3 | T3: =IF(COUNT(M3:R3)=0,"",SUM(M3:R3)) | U3: official | Y3: =IF(AND(A3="",B3="",D3="",COUNT(G3:L3)=0),"",IF(D3="","Missing shooter",IF(A3="","Missing date",IF(B3="","Missing event",IF(E3="","Club not in roster (type manually)",IF(COUNT(G3:L3)=0,"No scores entered",IF(U3="","Set status (official/provisional)",IF(COUNTIFS($A$2:$A$101,A3,$B$2:$B$101,B3,$D$2:$D$101,D3)>1,"Duplicate entry","OK to upload")))))))) -> OK to upload
E4: =IFERROR(IF(D4="","",VLOOKUP(D4,Members!$A$2:$C$16,2,FALSE())),"") | F4: =IFERROR(IF(D4="","",VLOOKUP(D4,Members!$A$2:$C$16,3,FALSE())),"") | S4: =IF(COUNT(G4:L4)=0,"",SUM(G4:L4)) | T4: =IF(COUNT(M4:R4)=0,"",SUM(M4:R4)) | Y4: =IF(AND(A4="",B4="",D4="",COUNT(G4:L4)=0),"",IF(D4="","Missing shooter",IF(A4="","Missing date",IF(B4="","Missing event",IF(E4="","Club not in roster (type manually)",IF(COUNT(G4:L4)=0,"No scores entered",IF(U4="","Set status (official/provisional)",IF(COUNTIFS($A$2:$A$101,A4,$B$2:$B$101,B4,$D$2:$D$101,D4)>1,"Duplicate entry","OK to upload"))))))))
E5: =IFERROR(IF(D5="","",VLOOKUP(D5,Members!$A$2:$C$16,2,FALSE())),"") | F5: =IFERROR(IF(D5="","",VLOOKUP(D5,Members!$A$2:$C$16,3,FALSE())),"") | S5: =IF(COUNT(G5:L5)=0,"",SUM(G5:L5)) | T5: =IF(COUNT(M5:R5)=0,"",SUM(M5:R5)) | Y5: =IF(AND(A5="",B5="",D5="",COUNT(G5:L5)=0),"",IF(D5="","Missing shooter",IF(A5="","Missing date",IF(B5="","Missing event",IF(E5="","Club not in roster (type manually)",IF(COUNT(G5:L5)=0,"No scores entered",IF(U5="","Set status (official/provisional)",IF(COUNTIFS($A$2:$A$101,A5,$B$2:$B$101,B5,$D$2:$D$101,D5)>1,"Duplicate entry","OK to upload"))))))))
E6: =IFERROR(IF(D6="","",VLOOKUP(D6,Members!$A$2:$C$16,2,FALSE())),"") | F6: =IFERROR(IF(D6="","",VLOOKUP(D6,Members!$A$2:$C$16,3,FALSE())),"") | S6: =IF(COUNT(G6:L6)=0,"",SUM(G6:L6)) | T6: =IF(COUNT(M6:R6)=0,"",SUM(M6:R6)) | Y6: =IF(AND(A6="",B6="",D6="",COUNT(G6:L6)=0),"",IF(D6="","Missing shooter",IF(A6="","Missing date",IF(B6="","Missing event",IF(E6="","Club not in roster (type manually)",IF(COUNT(G6:L6)=0,"No scores entered",IF(U6="","Set status (official/provisional)",IF(COUNTIFS($A$2:$A$101,A6,$B$2:$B$101,B6,$D$2:$D$101,D6)>1,"Duplicate entry","OK to upload"))))))))
E7: =IFERROR(IF(D7="","",VLOOKUP(D7,Members!$A$2:$C$16,2,FALSE())),"") | F7: =IFERROR(IF(D7="","",VLOOKUP(D7,Members!$A$2:$C$16,3,FALSE())),"") | S7: =IF(COUNT(G7:L7)=0,"",SUM(G7:L7)) | T7: =IF(COUNT(M7:R7)=0,"",SUM(M7:R7)) | Y7: =IF(AND(A7="",B7="",D7="",COUNT(G7:L7)=0),"",IF(D7="","Missing shooter",IF(A7="","Missing date",IF(B7="","Missing event",IF(E7="","Club not in roster (type manually)",IF(COUNT(G7:L7)=0,"No scores entered",IF(U7="","Set status (official/provisional)",IF(COUNTIFS($A$2:$A$101,A7,$B$2:$B$101,B7,$D$2:$D$101,D7)>1,"Duplicate entry","OK to upload"))))))))
E8: =IFERROR(IF(D8="","",VLOOKUP(D8,Members!$A$2:$C$16,2,FALSE())),"") | F8: =IFERROR(IF(D8="","",VLOOKUP(D8,Members!$A$2:$C$16,3,FALSE())),"") | S8: =IF(COUNT(G8:L8)=0,"",SUM(G8:L8)) | T8: =IF(COUNT(M8:R8)=0,"",SUM(M8:R8)) | Y8: =IF(AND(A8="",B8="",D8="",COUNT(G8:L8)=0),"",IF(D8="","Missing shooter",IF(A8="","Missing date",IF(B8="","Missing event",IF(E8="","Club not in roster (type manually)",IF(COUNT(G8:L8)=0,"No scores entered",IF(U8="","Set status (official/provisional)",IF(COUNTIFS($A$2:$A$101,A8,$B$2:$B$101,B8,$D$2:$D$101,D8)>1,"Duplicate entry","OK to upload"))))))))
E9: =IFERROR(IF(D9="","",VLOOKUP(D9,Members!$A$2:$C$16,2,FALSE())),"") | F9: =IFERROR(IF(D9="","",VLOOKUP(D9,Members!$A$2:$C$16,3,FALSE())),"") | S9: =IF(COUNT(G9:L9)=0,"",SUM(G9:L9)) | T9: =IF(COUNT(M9:R9)=0,"",SUM(M9:R9)) | Y9: =IF(AND(A9="",B9="",D9="",COUNT(G9:L9)=0),"",IF(D9="","Missing shooter",IF(A9="","Missing date",IF(B9="","Missing event",IF(E9="","Club not in roster (type manually)",IF(COUNT(G9:L9)=0,"No scores entered",IF(U9="","Set status (official/provisional)",IF(COUNTIFS($A$2:$A$101,A9,$B$2:$B$101,B9,$D$2:$D$101,D9)>1,"Duplicate entry","OK to upload"))))))))
E10: =IFERROR(IF(D10="","",VLOOKUP(D10,Members!$A$2:$C$16,2,FALSE())),"") | F10: =IFERROR(IF(D10="","",VLOOKUP(D10,Members!$A$2:$C$16,3,FALSE())),"") | S10: =IF(COUNT(G10:L10)=0,"",SUM(G10:L10)) | T10: =IF(COUNT(M10:R10)=0,"",SUM(M10:R10)) | Y10: =IF(AND(A10="",B10="",D10="",COUNT(G10:L10)=0),"",IF(D10="","Missing shooter",IF(A10="","Missing date",IF(B10="","Missing event",IF(E10="","Club not in roster (type manually)",IF(COUNT(G10:L10)=0,"No scores entered",IF(U10="","Set status (official/provisional)",IF(COUNTIFS($A$2:$A$101,A10,$B$2:$B$101,B10,$D$2:$D$101,D10)>1,"Duplicate entry","OK to upload"))))))))
E11: =IFERROR(IF(D11="","",VLOOKUP(D11,Members!$A$2:$C$16,2,FALSE())),"") | F11: =IFERROR(IF(D11="","",VLOOKUP(D11,Members!$A$2:$C$16,3,FALSE())),"") | S11: =IF(COUNT(G11:L11)=0,"",SUM(G11:L11)) | T11: =IF(COUNT(M11:R11)=0,"",SUM(M11:R11)) | Y11: =IF(AND(A11="",B11="",D11="",COUNT(G11:L11)=0),"",IF(D11="","Missing shooter",IF(A11="","Missing date",IF(B11="","Missing event",IF(E11="","Club not in roster (type manually)",IF(COUNT(G11:L11)=0,"No scores entered",IF(U11="","Set status (official/provisional)",IF(COUNTIFS($A$2:$A$101,A11,$B$2:$B$101,B11,$D$2:$D$101,D11)>1,"Duplicate entry","OK to upload"))))))))
E12: =IFERROR(IF(D12="","",VLOOKUP(D12,Members!$A$2:$C$16,2,FALSE())),"") | F12: =IFERROR(IF(D12="","",VLOOKUP(D12,Members!$A$2:$C$16,3,FALSE())),"") | S12: =IF(COUNT(G12:L12)=0,"",SUM(G12:L12)) | T12: =IF(COUNT(M12:R12)=0,"",SUM(M12:R12)) | Y12: =IF(AND(A12="",B12="",D12="",COUNT(G12:L12)=0),"",IF(D12="","Missing shooter",IF(A12="","Missing date",IF(B12="","Missing event",IF(E12="","Club not in roster (type manually)",IF(COUNT(G12:L12)=0,"No scores entered",IF(U12="","Set status (official/provisional)",IF(COUNTIFS($A$2:$A$101,A12,$B$2:$B$101,B12,$D$2:$D$101,D12)>1,"Duplicate entry","OK to upload"))))))))
E13: =IFERROR(IF(D13="","",VLOOKUP(D13,Members!$A$2:$C$16,2,FALSE())),"") | F13: =IFERROR(IF(D13="","",VLOOKUP(D13,Members!$A$2:$C$16,3,FALSE())),"") | S13: =IF(COUNT(G13:L13)=0,"",SUM(G13:L13)) | T13: =IF(COUNT(M13:R13)=0,"",SUM(M13:R13)) | Y13: =IF(AND(A13="",B13="",D13="",COUNT(G13:L13)=0),"",IF(D13="","Missing shooter",IF(A13="","Missing date",IF(B13="","Missing event",IF(E13="","Club not in roster (type manually)",IF(COUNT(G13:L13)=0,"No scores entered",IF(U13="","Set status (official/provisional)",IF(COUNTIFS($A$2:$A$101,A13,$B$2:$B$101,B13,$D$2:$D$101,D13)>1,"Duplicate entry","OK to upload"))))))))
E14: =IFERROR(IF(D14="","",VLOOKUP(D14,Members!$A$2:$C$16,2,FALSE())),"") | F14: =IFERROR(IF(D14="","",VLOOKUP(D14,Members!$A$2:$C$16,3,FALSE())),"") | S14: =IF(COUNT(G14:L14)=0,"",SUM(G14:L14)) | T14: =IF(COUNT(M14:R14)=0,"",SUM(M14:R14)) | Y14: =IF(AND(A14="",B14="",D14="",COUNT(G14:L14)=0),"",IF(D14="","Missing shooter",IF(A14="","Missing date",IF(B14="","Missing event",IF(E14="","Club not in roster (type manually)",IF(COUNT(G14:L14)=0,"No scores entered",IF(U14="","Set status (official/provisional)",IF(COUNTIFS($A$2:$A$101,A14,$B$2:$B$101,B14,$D$2:$D$101,D14)>1,"Duplicate entry","OK to upload"))))))))
E15: =IFERROR(IF(D15="","",VLOOKUP(D15,Members!$A$2:$C$16,2,FALSE())),"") | F15: =IFERROR(IF(D15="","",VLOOKUP(D15,Members!$A$2:$C$16,3,FALSE())),"") | S15: =IF(COUNT(G15:L15)=0,"",SUM(G15:L15)) | T15: =IF(COUNT(M15:R15)=0,"",SUM(M15:R15)) | Y15: =IF(AND(A15="",B15="",D15="",COUNT(G15:L15)=0),"",IF(D15="","Missing shooter",IF(A15="","Missing date",IF(B15="","Missing event",IF(E15="","Club not in roster (type manually)",IF(COUNT(G15:L15)=0,"No scores entered",IF(U15="","Set status (official/provisional)",IF(COUNTIFS($A$2:$A$101,A15,$B$2:$B$101,B15,$D$2:$D$101,D15)>1,"Duplicate entry","OK to upload"))))))))
... E101: =IFERROR(IF(D101="","",VLOOKUP(D101,Members!$A$2:$C$16,2,FALSE())),"") | F101: =IFERROR(IF(D101="","",VLOOKUP(D101,Members!$A$2:$C$16,3,FALSE())),"") | S101: =IF(COUNT(G101:L101)=0,"",SUM(G101:L101)) | T101: =IF(COUNT(M101:R101)=0,"",SUM(M101:R101)) | Y101: =IF(AND(A101="",B101="",D101="",COUNT(G101:L101)=0),"",IF(D101="","Missing shooter",IF(A101="","Missing date",IF(B101="","Missing event",IF(E101="","Club not in roster (type manually)",IF(COUNT(G101:L101)=0,"No scores entered",IF(U101="","Set status (official/provisional)",IF(COUNTIFS($A$2:$A$101,A101,$B$2:$B$101,B101,$D$2:$D$101,D101)>1,"Duplicate entry","OK to upload"))))))))

Sheet F-Class
A1: Date (YYYY-MM-DD) | B1: Event Name | C1: Discipline | D1: Shooter Name | E1: Club | F1: Category | G1: S1 Dec | H1: S2 Dec | I1: S3 Dec | J1: S4 Dec | K1: S5 Dec | L1: S6 Dec | M1: S1 Int | N1: S2 Int | O1: S3 Int | P1: S4 Int | Q1: S5 Int | R1: S6 Int | S1: Total Dec | T1: Total Int | U1: Status | V1: Notes | Y1: Check
A2: 2026-05-16 | B2: Club F-Class 600 | C2: fclass_open | D2: Pieter van Wyk | E2: =IFERROR(IF(D2="","",VLOOKUP(D2,Members!$A$2:$C$16,2,FALSE())),"") -> Pretoria RC | F2: =IFERROR(IF(D2="","",VLOOKUP(D2,Members!$A$2:$C$16,3,FALSE())),"") -> open | G2: 99 | H2: 98 | I2: 100 | J2: 97 | K2: 99 | L2: 98 | M2: 49 | N2: 48 | O2: 50 | P2: 47 | Q2: 49 | R2: 48 | S2: =IF(COUNT(G2:L2)=0,"",SUM(G2:L2)) -> 591 | T2: =IF(COUNT(M2:R2)=0,"",SUM(M2:R2)) -> 291 | U2: official | V2: Example — 6 series of 10 (2 diagrams of 5) | Y2: =IF(AND(A2="",B2="",D2="",COUNT(G2:L2)=0),"",IF(D2="","Missing shooter",IF(A2="","Missing date",IF(B2="","Missing event",IF(E2="","Club not in roster (type manually)",IF(COUNT(G2:L2)=0,"No scores entered",IF(U2="","Set status (official/provisional)",IF(COUNTIFS($A$2:$A$101,A2,$B$2:$B$101,B2,$D$2:$D$101,D2)>1,"Duplicate entry","OK to upload")))))))) -> OK to upload
E3: =IFERROR(IF(D3="","",VLOOKUP(D3,Members!$A$2:$C$16,2,FALSE())),"") | F3: =IFERROR(IF(D3="","",VLOOKUP(D3,Members!$A$2:$C$16,3,FALSE())),"") | S3: =IF(COUNT(G3:L3)=0,"",SUM(G3:L3)) | T3: =IF(COUNT(M3:R3)=0,"",SUM(M3:R3)) | Y3: =IF(AND(A3="",B3="",D3="",COUNT(G3:L3)=0),"",IF(D3="","Missing shooter",IF(A3="","Missing date",IF(B3="","Missing event",IF(E3="","Club not in roster (type manually)",IF(COUNT(G3:L3)=0,"No scores entered",IF(U3="","Set status (official/provisional)",IF(COUNTIFS($A$2:$A$101,A3,$B$2:$B$101,B3,$D$2:$D$101,D3)>1,"Duplicate entry","OK to upload"))))))))
E4: =IFERROR(IF(D4="","",VLOOKUP(D4,Members!$A$2:$C$16,2,FALSE())),"") | F4: =IFERROR(IF(D4="","",VLOOKUP(D4,Members!$A$2:$C$16,3,FALSE())),"") | S4: =IF(COUNT(G4:L4)=0,"",SUM(G4:L4)) | T4: =IF(COUNT(M4:R4)=0,"",SUM(M4:R4)) | Y4: =IF(AND(A4="",B4="",D4="",COUNT(G4:L4)=0),"",IF(D4="","Missing shooter",IF(A4="","Missing date",IF(B4="","Missing event",IF(E4="","Club not in roster (type manually)",IF(COUNT(G4:L4)=0,"No scores entered",IF(U4="","Set status (official/provisional)",IF(COUNTIFS($A$2:$A$101,A4,$B$2:$B$101,B4,$D$2:$D$101,D4)>1,"Duplicate entry","OK to upload"))))))))
E5: =IFERROR(IF(D5="","",VLOOKUP(D5,Members!$A$2:$C$16,2,FALSE())),"") | F5: =IFERROR(IF(D5="","",VLOOKUP(D5,Members!$A$2:$C$16,3,FALSE())),"") | S5: =IF(COUNT(G5:L5)=0,"",SUM(G5:L5)) | T5: =IF(COUNT(M5:R5)=0,"",SUM(M5:R5)) | Y5: =IF(AND(A5="",B5="",D5="",COUNT(G5:L5)=0),"",IF(D5="","Missing shooter",IF(A5="","Missing date",IF(B5="","Missing event",IF(E5="","Club not in roster (type manually)",IF(COUNT(G5:L5)=0,"No scores entered",IF(U5="","Set status (official/provisional)",IF(COUNTIFS($A$2:$A$101,A5,$B$2:$B$101,B5,$D$2:$D$101,D5)>1,"Duplicate entry","OK to upload"))))))))
E6: =IFERROR(IF(D6="","",VLOOKUP(D6,Members!$A$2:$C$16,2,FALSE())),"") | F6: =IFERROR(IF(D6="","",VLOOKUP(D6,Members!$A$2:$C$16,3,FALSE())),"") | S6: =IF(COUNT(G6:L6)=0,"",SUM(G6:L6)) | T6: =IF(COUNT(M6:R6)=0,"",SUM(M6:R6)) | Y6: =IF(AND(A6="",B6="",D6="",COUNT(G6:L6)=0),"",IF(D6="","Missing shooter",IF(A6="","Missing date",IF(B6="","Missing event",IF(E6="","Club not in roster (type manually)",IF(COUNT(G6:L6)=0,"No scores entered",IF(U6="","Set status (official/provisional)",IF(COUNTIFS($A$2:$A$101,A6,$B$2:$B$101,B6,$D$2:$D$101,D6)>1,"Duplicate entry","OK to upload"))))))))
E7: =IFERROR(IF(D7="","",VLOOKUP(D7,Members!$A$2:$C$16,2,FALSE())),"") | F7: =IFERROR(IF(D7="","",VLOOKUP(D7,Members!$A$2:$C$16,3,FALSE())),"") | S7: =IF(COUNT(G7:L7)=0,"",SUM(G7:L7)) | T7: =IF(COUNT(M7:R7)=0,"",SUM(M7:R7)) | Y7: =IF(AND(A7="",B7="",D7="",COUNT(G7:L7)=0),"",IF(D7="","Missing shooter",IF(A7="","Missing date",IF(B7="","Missing event",IF(E7="","Club not in roster (type manually)",IF(COUNT(G7:L7)=0,"No scores entered",IF(U7="","Set status (official/provisional)",IF(COUNTIFS($A$2:$A$101,A7,$B$2:$B$101,B7,$D$2:$D$101,D7)>1,"Duplicate entry","OK to upload"))))))))
E8: =IFERROR(IF(D8="","",VLOOKUP(D8,Members!$A$2:$C$16,2,FALSE())),"") | F8: =IFERROR(IF(D8="","",VLOOKUP(D8,Members!$A$2:$C$16,3,FALSE())),"") | S8: =IF(COUNT(G8:L8)=0,"",SUM(G8:L8)) | T8: =IF(COUNT(M8:R8)=0,"",SUM(M8:R8)) | Y8: =IF(AND(A8="",B8="",D8="",COUNT(G8:L8)=0),"",IF(D8="","Missing shooter",IF(A8="","Missing date",IF(B8="","Missing event",IF(E8="","Club not in roster (type manually)",IF(COUNT(G8:L8)=0,"No scores entered",IF(U8="","Set status (official/provisional)",IF(COUNTIFS($A$2:$A$101,A8,$B$2:$B$101,B8,$D$2:$D$101,D8)>1,"Duplicate entry","OK to upload"))))))))
E9: =IFERROR(IF(D9="","",VLOOKUP(D9,Members!$A$2:$C$16,2,FALSE())),"") | F9: =IFERROR(IF(D9="","",VLOOKUP(D9,Members!$A$2:$C$16,3,FALSE())),"") | S9: =IF(COUNT(G9:L9)=0,"",SUM(G9:L9)) | T9: =IF(COUNT(M9:R9)=0,"",SUM(M9:R9)) | Y9: =IF(AND(A9="",B9="",D9="",COUNT(G9:L9)=0),"",IF(D9="","Missing shooter",IF(A9="","Missing date",IF(B9="","Missing event",IF(E9="","Club not in roster (type manually)",IF(COUNT(G9:L9)=0,"No scores entered",IF(U9="","Set status (official/provisional)",IF(COUNTIFS($A$2:$A$101,A9,$B$2:$B$101,B9,$D$2:$D$101,D9)>1,"Duplicate entry","OK to upload"))))))))
E10: =IFERROR(IF(D10="","",VLOOKUP(D10,Members!$A$2:$C$16,2,FALSE())),"") | F10: =IFERROR(IF(D10="","",VLOOKUP(D10,Members!$A$2:$C$16,3,FALSE())),"") | S10: =IF(COUNT(G10:L10)=0,"",SUM(G10:L10)) | T10: =IF(COUNT(M10:R10)=0,"",SUM(M10:R10)) | Y10: =IF(AND(A10="",B10="",D10="",COUNT(G10:L10)=0),"",IF(D10="","Missing shooter",IF(A10="","Missing date",IF(B10="","Missing event",IF(E10="","Club not in roster (type manually)",IF(COUNT(G10:L10)=0,"No scores entered",IF(U10="","Set status (official/provisional)",IF(COUNTIFS($A$2:$A$101,A10,$B$2:$B$101,B10,$D$2:$D$101,D10)>1,"Duplicate entry","OK to upload"))))))))
E11: =IFERROR(IF(D11="","",VLOOKUP(D11,Members!$A$2:$C$16,2,FALSE())),"") | F11: =IFERROR(IF(D11="","",VLOOKUP(D11,Members!$A$2:$C$16,3,FALSE())),"") | S11: =IF(COUNT(G11:L11)=0,"",SUM(G11:L11)) | T11: =IF(COUNT(M11:R11)=0,"",SUM(M11:R11)) | Y11: =IF(AND(A11="",B11="",D11="",COUNT(G11:L11)=0),"",IF(D11="","Missing shooter",IF(A11="","Missing date",IF(B11="","Missing event",IF(E11="","Club not in roster (type manually)",IF(COUNT(G11:L11)=0,"No scores entered",IF(U11="","Set status (official/provisional)",IF(COUNTIFS($A$2:$A$101,A11,$B$2:$B$101,B11,$D$2:$D$101,D11)>1,"Duplicate entry","OK to upload"))))))))
E12: =IFERROR(IF(D12="","",VLOOKUP(D12,Members!$A$2:$C$16,2,FALSE())),"") | F12: =IFERROR(IF(D12="","",VLOOKUP(D12,Members!$A$2:$C$16,3,FALSE())),"") | S12: =IF(COUNT(G12:L12)=0,"",SUM(G12:L12)) | T12: =IF(COUNT(M12:R12)=0,"",SUM(M12:R12)) | Y12: =IF(AND(A12="",B12="",D12="",COUNT(G12:L12)=0),"",IF(D12="","Missing shooter",IF(A12="","Missing date",IF(B12="","Missing event",IF(E12="","Club not in roster (type manually)",IF(COUNT(G12:L12)=0,"No scores entered",IF(U12="","Set status (official/provisional)",IF(COUNTIFS($A$2:$A$101,A12,$B$2:$B$101,B12,$D$2:$D$101,D12)>1,"Duplicate entry","OK to upload"))))))))
E13: =IFERROR(IF(D13="","",VLOOKUP(D13,Members!$A$2:$C$16,2,FALSE())),"") | F13: =IFERROR(IF(D13="","",VLOOKUP(D13,Members!$A$2:$C$16,3,FALSE())),"") | S13: =IF(COUNT(G13:L13)=0,"",SUM(G13:L13)) | T13: =IF(COUNT(M13:R13)=0,"",SUM(M13:R13)) | Y13: =IF(AND(A13="",B13="",D13="",COUNT(G13:L13)=0),"",IF(D13="","Missing shooter",IF(A13="","Missing date",IF(B13="","Missing event",IF(E13="","Club not in roster (type manually)",IF(COUNT(G13:L13)=0,"No scores entered",IF(U13="","Set status (official/provisional)",IF(COUNTIFS($A$2:$A$101,A13,$B$2:$B$101,B13,$D$2:$D$101,D13)>1,"Duplicate entry","OK to upload"))))))))
E14: =IFERROR(IF(D14="","",VLOOKUP(D14,Members!$A$2:$C$16,2,FALSE())),"") | F14: =IFERROR(IF(D14="","",VLOOKUP(D14,Members!$A$2:$C$16,3,FALSE())),"") | S14: =IF(COUNT(G14:L14)=0,"",SUM(G14:L14)) | T14: =IF(COUNT(M14:R14)=0,"",SUM(M14:R14)) | Y14: =IF(AND(A14="",B14="",D14="",COUNT(G14:L14)=0),"",IF(D14="","Missing shooter",IF(A14="","Missing date",IF(B14="","Missing event",IF(E14="","Club not in roster (type manually)",IF(COUNT(G14:L14)=0,"No scores entered",IF(U14="","Set status (official/provisional)",IF(COUNTIFS($A$2:$A$101,A14,$B$2:$B$101,B14,$D$2:$D$101,D14)>1,"Duplicate entry","OK to upload"))))))))
... E101: =IFERROR(IF(D101="","",VLOOKUP(D101,Members!$A$2:$C$16,2,FALSE())),"") | F101: =IFERROR(IF(D101="","",VLOOKUP(D101,Members!$A$2:$C$16,3,FALSE())),"") | S101: =IF(COUNT(G101:L101)=0,"",SUM(G101:L101)) | T101: =IF(COUNT(M101:R101)=0,"",SUM(M101:R101)) | Y101: =IF(AND(A101="",B101="",D101="",COUNT(G101:L101)=0),"",IF(D101="","Missing shooter",IF(A101="","Missing date",IF(B101="","Missing event",IF(E101="","Club not in roster (type manually)",IF(COUNT(G101:L101)=0,"No scores entered",IF(U101="","Set status (official/provisional)",IF(COUNTIFS($A$2:$A$101,A101,$B$2:$B$101,B101,$D$2:$D$101,D101)>1,"Duplicate entry","OK to upload"))))))))

Sheet 3-Position 50m
A1: 3-Position 50m — QUALIFICATION (2 series per position, decimal)
A2: 60 shots: Kneeling, Prone, Standing — each 2 series of 10. Enter the decimal total of each series (max 109.0). Total auto-sums (max 654.0). Order of fire: Kneeling, Prone, Standing.
A4: Date (YYYY-MM-DD) | B4: Event Name | C4: Discipline | D4: Shooter Name | E4: Club | F4: Category | G4: Kn S1 | H4: Kn S2 | I4: Pr S1 | J4: Pr S2 | K4: St S1 | L4: St S2 | M4: Total Dec | N4: Status | O4: Notes | R4: Check
A5: 2026-05-23 | B5: 3-Position Open | C5: three_position_50m | D5: Lerato Dlamini | E5: SATRF Club | F5: junior | G5: 104.9 | H5: 104 | I5: 105.1 | J5: 104.4 | K5: 104.3 | L5: 104.2 | M5: =IF(COUNT(G5:L5)=6,ROUND(SUM(G5:L5),1),"") -> 626.9 | N5: official | O5: Example — 2 series per position | R5: =IF(COUNT(G5:L5)=6,"OK to upload","Fill all 6 series") -> OK to upload
M6: =IF(COUNT(G6:L6)=6,ROUND(SUM(G6:L6),1),"") | R6: =IF(COUNT(G6:L6)=6,"OK to upload",IF(COUNT(G6:L6)=0,"","Fill all 6 series"))
M7: =IF(COUNT(G7:L7)=6,ROUND(SUM(G7:L7),1),"") | R7: =IF(COUNT(G7:L7)=6,"OK to upload",IF(COUNT(G7:L7)=0,"","Fill all 6 series"))
M8: =IF(COUNT(G8:L8)=6,ROUND(SUM(G8:L8),1),"") | R8: =IF(COUNT(G8:L8)=6,"OK to upload",IF(COUNT(G8:L8)=0,"","Fill all 6 series"))
M9: =IF(COUNT(G9:L9)=6,ROUND(SUM(G9:L9),1),"") | R9: =IF(COUNT(G9:L9)=6,"OK to upload",IF(COUNT(G9:L9)=0,"","Fill all 6 series"))
M10: =IF(COUNT(G10:L10)=6,ROUND(SUM(G10:L10),1),"") | R10: =IF(COUNT(G10:L10)=6,"OK to upload",IF(COUNT(G10:L10)=0,"","Fill all 6 series"))
M11: =IF(COUNT(G11:L11)=6,ROUND(SUM(G11:L11),1),"") | R11: =IF(COUNT(G11:L11)=6,"OK to upload",IF(COUNT(G11:L11)=0,"","Fill all 6 series"))
M12: =IF(COUNT(G12:L12)=6,ROUND(SUM(G12:L12),1),"") | R12: =IF(COUNT(G12:L12)=6,"OK to upload",IF(COUNT(G12:L12)=0,"","Fill all 6 series"))
M13: =IF(COUNT(G13:L13)=6,ROUND(SUM(G13:L13),1),"") | R13: =IF(COUNT(G13:L13)=6,"OK to upload",IF(COUNT(G13:L13)=0,"","Fill all 6 series"))
M14: =IF(COUNT(G14:L14)=6,ROUND(SUM(G14:L14),1),"") | R14: =IF(COUNT(G14:L14)=6,"OK to upload",IF(COUNT(G14:L14)=0,"","Fill all 6 series"))
M15: =IF(COUNT(G15:L15)=6,ROUND(SUM(G15:L15),1),"") | R15: =IF(COUNT(G15:L15)=6,"OK to upload",IF(COUNT(G15:L15)=0,"","Fill all 6 series"))
M16: =IF(COUNT(G16:L16)=6,ROUND(SUM(G16:L16),1),"") | R16: =IF(COUNT(G16:L16)=6,"OK to upload",IF(COUNT(G16:L16)=0,"","Fill all 6 series"))
M17: =IF(COUNT(G17:L17)=6,ROUND(SUM(G17:L17),1),"") | R17: =IF(COUNT(G17:L17)=6,"OK to upload",IF(COUNT(G17:L17)=0,"","Fill all 6 series"))
... M60: =IF(COUNT(G60:L60)=6,ROUND(SUM(G60:L60),1),"") | R60: =IF(COUNT(G60:L60)=6,"OK to upload",IF(COUNT(G60:L60)=0,"","Fill all 6 series"))

Sheet 3P Final
A1: 3P Final — ISSF 35-shot ladder (decimal)
A2: Starts from ZERO. Kneeling 10 (2×5), Prone 10 (2×5), Standing 2×5 series, then SINGLE-shot elimination (shots 31–35). Enter each value; LEAVE BLANK once the athlete is eliminated. Total auto-sums whatever was fired. Order: Kn, Pr, Standing series, then singles. Winner fires all 35; lower placers fewer.
A4: Match ID | B4: Date | C4: Discipline | D4: Shooter Name | E4: Club | F4: Category | G4: Kn S1 | H4: Kn S2 | I4: Pr S1 | J4: Pr S2 | K4: Std S1 | L4: Std S2 | M4: Elim 1 | N4: Elim 2 | O4: Elim 3 | P4: Elim 4 | Q4: Elim 5 | R4: Total Dec | S4: Final Rank | T4: Status | U4: Notes
A5: M002 | B5: 2026-05-23 | C5: three_position_50m | D5: Lerato Dlamini | E5: SATRF Club | F5: junior | G5: 51.1 | H5: 50.5 | I5: 51.8 | J5: 52.7 | K5: 51.1 | L5: 51.8 | M5: 10.1 | N5: 10.8 | O5: 10.3 | P5: 10 | Q5: 9.8 | R5: =ROUND(SUM(G5:Q5),1) -> 360 | S5: 1 | T5: official | U5: Winner — fires all 35 (full ladder). Each col = 5-shot series; Elim = single shots.
R6: =IF(COUNT(G6:Q6)>0,ROUND(SUM(G6:Q6),1),"")
R7: =IF(COUNT(G7:Q7)>0,ROUND(SUM(G7:Q7),1),"")
R8: =IF(COUNT(G8:Q8)>0,ROUND(SUM(G8:Q8),1),"")
R9: =IF(COUNT(G9:Q9)>0,ROUND(SUM(G9:Q9),1),"")
R10: =IF(COUNT(G10:Q10)>0,ROUND(SUM(G10:Q10),1),"")
R11: =IF(COUNT(G11:Q11)>0,ROUND(SUM(G11:Q11),1),"")
R12: =IF(COUNT(G12:Q12)>0,ROUND(SUM(G12:Q12),1),"")
R13: =IF(COUNT(G13:Q13)>0,ROUND(SUM(G13:Q13),1),"")
R14: =IF(COUNT(G14:Q14)>0,ROUND(SUM(G14:Q14),1),"")
R15: =IF(COUNT(G15:Q15)>0,ROUND(SUM(G15:Q15),1),"")
R16: =IF(COUNT(G16:Q16)>0,ROUND(SUM(G16:Q16),1),"")
R17: =IF(COUNT(G17:Q17)>0,ROUND(SUM(G17:Q17),1),"")
... R60: =IF(COUNT(G60:Q60)>0,ROUND(SUM(G60:Q60),1),"")
A62: Series columns (Kn/Pr/Std S1/S2) are 5-shot series totals (max ~54.5). Elim columns are single decimal shots (max 10.9). Leave blanks after elimination — Total sums only fired shots.

Sheet Prone Final
A1: Prone Final — 6 series (decimal)
A2: Separate stage, starts from ZERO (not added to qualification). Enter the 6 series decimals (max 109.0 each). Total auto-sums (max 654.0). Enter finishing Rank.
A4: Match ID | B4: Date | C4: Discipline | D4: Shooter Name | E4: Club | F4: Category | G4: S1 | H4: S2 | I4: S3 | J4: S4 | K4: S5 | L4: S6 | M4: Total Dec | N4: Final Rank | O4: Status | P4: Notes
A5: M001 | B5: 2026-05-09 | C5: prone_50m | D5: Arnold Prone | E5: Modderbee | F5: open | G5: 100 | H5: 101 | I5: 101.4 | J5: 98.4 | K5: 94 | L5: 95 | M5: =IF(COUNT(G5:L5)=6,ROUND(SUM(G5:L5),1),"") -> 589.8 | N5: 1 | O5: official | P5: Prone final example
M6: =IF(COUNT(G6:L6)=6,ROUND(SUM(G6:L6),1),"")
M7: =IF(COUNT(G7:L7)=6,ROUND(SUM(G7:L7),1),"")
M8: =IF(COUNT(G8:L8)=6,ROUND(SUM(G8:L8),1),"")
M9: =IF(COUNT(G9:L9)=6,ROUND(SUM(G9:L9),1),"")
M10: =IF(COUNT(G10:L10)=6,ROUND(SUM(G10:L10),1),"")
M11: =IF(COUNT(G11:L11)=6,ROUND(SUM(G11:L11),1),"")
M12: =IF(COUNT(G12:L12)=6,ROUND(SUM(G12:L12),1),"")
M13: =IF(COUNT(G13:L13)=6,ROUND(SUM(G13:L13),1),"")
M14: =IF(COUNT(G14:L14)=6,ROUND(SUM(G14:L14),1),"")
M15: =IF(COUNT(G15:L15)=6,ROUND(SUM(G15:L15),1),"")
M16: =IF(COUNT(G16:L16)=6,ROUND(SUM(G16:L16),1),"")
M17: =IF(COUNT(G17:L17)=6,ROUND(SUM(G17:L17),1),"")
... M60: =IF(COUNT(G60:L60)=6,ROUND(SUM(G60:L60),1),"")

Sheet Results
A1: Overall Results (ISSF ranking)
A2: Pick a Match ID below. Finalists are ranked by their FINAL result (start-from-zero) on top; everyone else is ranked by QUALIFICATION score beneath. Scores are never added — ISSF rule.
A4: Show Match ID: | B4: M002 | C4: =IFERROR("("&VLOOKUP(B4,'Match Setup'!$A$5:$G$25,2,FALSE())&" — "&VLOOKUP(B4,'Match Setup'!$A$5:$G$25,4,FALSE())&", Final: "&VLOOKUP(B4,'Match Setup'!$A$5:$G$25,5,FALSE())&")","") -> (Open 3P Champs — three_position_50m, Final: Yes)
A6: Overall Rank | B6: Shooter | C6: Stage that decides | D6: Qualification | E6: Final | F6: Final Rank
C7: =IF(B7="","",IF(F7<>"","Final","Qualification"))
C8: =IF(B8="","",IF(F8<>"","Final","Qualification"))
C9: =IF(B9="","",IF(F9<>"","Final","Qualification"))
C10: =IF(B10="","",IF(F10<>"","Final","Qualification"))
C11: =IF(B11="","",IF(F11<>"","Final","Qualification"))
C12: =IF(B12="","",IF(F12<>"","Final","Qualification"))
C13: =IF(B13="","",IF(F13<>"","Final","Qualification"))
C14: =IF(B14="","",IF(F14<>"","Final","Qualification"))
C15: =IF(B15="","",IF(F15<>"","Final","Qualification"))
C16: =IF(B16="","",IF(F16<>"","Final","Qualification"))
C17: =IF(B17="","",IF(F17<>"","Final","Qualification"))
C18: =IF(B18="","",IF(F18<>"","Final","Qualification"))
... C26: =IF(B26="","",IF(F26<>"","Final","Qualification"))
A28: How to use: list each shooter once. Enter their Qualification total (from the qual tab) and, if they shot the final, their Final total + Final Rank (from the Finals tab). The 'Stage that decides' column shows which score sets their place. Finalists outrank non-finalists per ISSF.

Sheet Export (Upload)
A1: Combined Export — upload-ready
A2: One flat row per shooter per stage. 'Stage' = Qualification or Final. This can be uploaded as a single file, OR filtered by Stage and uploaded as two files (qualification first, then final). Adjust column names/order to match your website's importer.
A3: Match ID | B3: Date | C3: Discipline | D3: Stage | E3: Shooter | F3: Club | G3: Category | H3: Score (decimal) | I3: Final Rank | J3: Status

Sheet Season & PB
A1: Season & Personal Best Tracking
A2: Pick a shooter and a discipline. Shows all-time and current-season best & average, in decimal and integer. Updates automatically from the score tabs.
A4: Shooter: | B4: Arnold Prone | D4: Discipline: | E4: prone_50m | G4: Season (year): | H4: 2026
A6: Metric | B6: All-time (Dec) | C6: All-time (Int) | D6: Season (Dec) | E6: Season (Int)
A7: Matches shot | B7: =COUNTIFS(AllScores!$I$2:$I$301,1,AllScores!$B$2:$B$301,$E$4,AllScores!$C$2:$C$301,$B$4) -> 1 | C7: =COUNTIFS(AllScores!$I$2:$I$301,1,AllScores!$B$2:$B$301,$E$4,AllScores!$C$2:$C$301,$B$4) -> 1 | D7: =COUNTIFS(AllScores!$I$2:$I$301,1,AllScores!$B$2:$B$301,$E$4,AllScores!$C$2:$C$301,$B$4,AllScores!$H$2:$H$301,$H$4) -> 1 | E7: =COUNTIFS(AllScores!$I$2:$I$301,1,AllScores!$B$2:$B$301,$E$4,AllScores!$C$2:$C$301,$B$4,AllScores!$H$2:$H$301,$H$4) -> 1
A8: Personal best | B8: =IFERROR(SUMPRODUCT(MAX(((AllScores!$B$2:$B$301=$E$4)*(AllScores!$C$2:$C$301=$B$4)*(AllScores!$I$2:$I$301=1))*AllScores!$F$2:$F$301)),"") | C8: =IFERROR(SUMPRODUCT(MAX(((AllScores!$B$2:$B$301=$E$4)*(AllScores!$C$2:$C$301=$B$4)*(AllScores!$I$2:$I$301=1))*AllScores!$G$2:$G$301)),"") | D8: =IFERROR(SUMPRODUCT(MAX(((AllScores!$B$2:$B$301=$E$4)*(AllScores!$C$2:$C$301=$B$4)*(AllScores!$I$2:$I$301=1)*(AllScores!$H$2:$H$301=$H$4))*AllScores!$F$2:$F$301)),"") | E8: =IFERROR(SUMPRODUCT(MAX(((AllScores!$B$2:$B$301=$E$4)*(AllScores!$C$2:$C$301=$B$4)*(AllScores!$I$2:$I$301=1)*(AllScores!$H$2:$H$301=$H$4))*AllScores!$G$2:$G$301)),"")
A9: Average | B9: =IFERROR(AVERAGEIFS(AllScores!$F$2:$F$301,AllScores!$B$2:$B$301,$E$4,AllScores!$C$2:$C$301,$B$4,AllScores!$I$2:$I$301,1),"") -> 600.4 | C9: =IFERROR(AVERAGEIFS(AllScores!$G$2:$G$301,AllScores!$B$2:$B$301,$E$4,AllScores!$C$2:$C$301,$B$4,AllScores!$I$2:$I$301,1),"") -> 567 | D9: =IFERROR(AVERAGEIFS(AllScores!$F$2:$F$301,AllScores!$B$2:$B$301,$E$4,AllScores!$C$2:$C$301,$B$4,AllScores!$I$2:$I$301,1,AllScores!$H$2:$H$301,$H$4),"") -> 600.4 | E9: =IFERROR(AVERAGEIFS(AllScores!$G$2:$G$301,AllScores!$B$2:$B$301,$E$4,AllScores!$C$2:$C$301,$B$4,AllScores!$I$2:$I$301,1,AllScores!$H$2:$H$301,$H$4),"") -> 567
A10: Lowest | B10: =IFERROR(SUMPRODUCT(MIN(AllScores!$F$2:$F$301+(1-((AllScores!$B$2:$B$301=$E$4)*(AllScores!$C$2:$C$301=$B$4)*(AllScores!$I$2:$I$301=1)))*1000000)),"") | C10: =IFERROR(SUMPRODUCT(MIN(AllScores!$G$2:$G$301+(1-((AllScores!$B$2:$B$301=$E$4)*(AllScores!$C$2:$C$301=$B$4)*(AllScores!$I$2:$I$301=1)))*1000000)),"") | D10: =IFERROR(SUMPRODUCT(MIN(AllScores!$F$2:$F$301+(1-((AllScores!$B$2:$B$301=$E$4)*(AllScores!$C$2:$C$301=$B$4)*(AllScores!$I$2:$I$301=1)*(AllScores!$H$2:$H$301=$H$4)))*1000000)),"") | E10: =IFERROR(SUMPRODUCT(MIN(AllScores!$G$2:$G$301+(1-((AllScores!$B$2:$B$301=$E$4)*(AllScores!$C$2:$C$301=$B$4)*(AllScores!$I$2:$I$301=1)*(AllScores!$H$2:$H$301=$H$4)))*1000000)),"")
A12: Note: 'best' is the highest match total. Decimal and integer shown side by side. Season view uses the year in H4. Array formulas — totals recalc on open.

Sheet Class Records
A1: Class Records — by Discipline & Category
A2: Best decimal & integer total recorded for each discipline/category combination, with who holds it and when. Auto-updates as scores are entered.
A4: Discipline | B4: Category | C4: Record (Dec) | D4: Holder (Dec) | E4: Date (Dec) | F4: Record (Int) | G4: Holder (Int) | H4: Date (Int)
A5: prone_50m | B5: open | C5: =IFERROR(IF(SUMPRODUCT((AllScores!$B$2:$B$301=$A5)*(AllScores!$E$2:$E$301=$B5)*(AllScores!$I$2:$I$301=1))=0,"",IF(SUMPRODUCT(MAX(((AllScores!$B$2:$B$301=$A5)*(AllScores!$E$2:$E$301=$B5)*(AllScores!$I$2:$I$301=1))*AllScores!$F$2:$F$301))=0,"",SUMPRODUCT(MAX(((AllScores!$B$2:$B$301=$A5)*(AllScores!$E$2:$E$301=$B5)*(AllScores!$I$2:$I$301=1))*AllScores!$F$2:$F$301)))),"") | D5: {=IF($C5="","",IFERROR(INDEX(AllScores!$C$2:$C$301,SUMPRODUCT(((AllScores!$B$2:$B$301=$A5)*(AllScores!$E$2:$E$301=$B5)*(AllScores!$I$2:$I$301=1))*(AllScores!$F$2:$F$301=$C5)*(ROW(AllScores!$F$2:$F$301)-1))),""))} | E5: {=IF($C5="","",IFERROR(INDEX(AllScores!$A$2:$A$301,SUMPRODUCT(((AllScores!$B$2:$B$301=$A5)*(AllScores!$E$2:$E$301=$B5)*(AllScores!$I$2:$I$301=1))*(AllScores!$F$2:$F$301=$C5)*(ROW(AllScores!$A$2:$A$301)-1))),""))} | F5: =IFERROR(IF(SUMPRODUCT((AllScores!$B$2:$B$301=$A5)*(AllScores!$E$2:$E$301=$B5)*(AllScores!$I$2:$I$301=1))=0,"",IF(SUMPRODUCT(MAX(((AllScores!$B$2:$B$301=$A5)*(AllScores!$E$2:$E$301=$B5)*(AllScores!$I$2:$I$301=1))*AllScores!$G$2:$G$301))=0,"",SUMPRODUCT(MAX(((AllScores!$B$2:$B$301=$A5)*(AllScores!$E$2:$E$301=$B5)*(AllScores!$I$2:$I$301=1))*AllScores!$G$2:$G$301)))),"") | G5: {=IF($F5="","",IFERROR(INDEX(AllScores!$C$2:$C$301,SUMPRODUCT(((AllScores!$B$2:$B$301=$A5)*(AllScores!$E$2:$E$301=$B5)*(AllScores!$I$2:$I$301=1))*(AllScores!$G$2:$G$301=$F5)*(ROW(AllScores!$G$2:$G$301)-1))),""))} | H5: {=IF($F5="","",IFERROR(INDEX(AllScores!$A$2:$A$301,SUMPRODUCT(((AllScores!$B$2:$B$301=$A5)*(AllScores!$E$2:$E$301=$B5)*(AllScores!$I$2:$I$301=1))*(AllScores!$G$2:$G$301=$F5)*(ROW(AllScores!$A$2:$A$301)-1))),""))}
A6: prone_50m | B6: junior | C6: =IFERROR(IF(SUMPRODUCT((AllScores!$B$2:$B$301=$A6)*(AllScores!$E$2:$E$301=$B6)*(AllScores!$I$2:$I$301=1))=0,"",IF(SUMPRODUCT(MAX(((AllScores!$B$2:$B$301=$A6)*(AllScores!$E$2:$E$301=$B6)*(AllScores!$I$2:$I$301=1))*AllScores!$F$2:$F$301))=0,"",SUMPRODUCT(MAX(((AllScores!$B$2:$B$301=$A6)*(AllScores!$E$2:$E$301=$B6)*(AllScores!$I$2:$I$301=1))*AllScores!$F$2:$F$301)))),"") | D6: {=IF($C6="","",IFERROR(INDEX(AllScores!$C$2:$C$301,SUMPRODUCT(((AllScores!$B$2:$B$301=$A6)*(AllScores!$E$2:$E$301=$B6)*(AllScores!$I$2:$I$301=1))*(AllScores!$F$2:$F$301=$C6)*(ROW(AllScores!$F$2:$F$301)-1))),""))} | E6: {=IF($C6="","",IFERROR(INDEX(AllScores!$A$2:$A$301,SUMPRODUCT(((AllScores!$B$2:$B$301=$A6)*(AllScores!$E$2:$E$301=$B6)*(AllScores!$I$2:$I$301=1))*(AllScores!$F$2:$F$301=$C6)*(ROW(AllScores!$A$2:$A$301)-1))),""))} | F6: =IFERROR(IF(SUMPRODUCT((AllScores!$B$2:$B$301=$A6)*(AllScores!$E$2:$E$301=$B6)*(AllScores!$I$2:$I$301=1))=0,"",IF(SUMPRODUCT(MAX(((AllScores!$B$2:$B$301=$A6)*(AllScores!$E$2:$E$301=$B6)*(AllScores!$I$2:$I$301=1))*AllScores!$G$2:$G$301))=0,"",SUMPRODUCT(MAX(((AllScores!$B$2:$B$301=$A6)*(AllScores!$E$2:$E$301=$B6)*(AllScores!$I$2:$I$301=1))*AllScores!$G$2:$G$301)))),"") | G6: {=IF($F6="","",IFERROR(INDEX(AllScores!$C$2:$C$301,SUMPRODUCT(((AllScores!$B$2:$B$301=$A6)*(AllScores!$E$2:$E$301=$B6)*(AllScores!$I$2:$I$301=1))*(AllScores!$G$2:$G$301=$F6)*(ROW(AllScores!$G$2:$G$301)-1))),""))} | H6: {=IF($F6="","",IFERROR(INDEX(AllScores!$A$2:$A$301,SUMPRODUCT(((AllScores!$B$2:$B$301=$A6)*(AllScores!$E$2:$E$301=$B6)*(AllScores!$I$2:$I$301=1))*(AllScores!$G$2:$G$301=$F6)*(ROW(AllScores!$A$2:$A$301)-1))),""))}
A7: prone_50m | B7: veteran | C7: =IFERROR(IF(SUMPRODUCT((AllScores!$B$2:$B$301=$A7)*(AllScores!$E$2:$E$301=$B7)*(AllScores!$I$2:$I$301=1))=0,"",IF(SUMPRODUCT(MAX(((AllScores!$B$2:$B$301=$A7)*(AllScores!$E$2:$E$301=$B7)*(AllScores!$I$2:$I$301=1))*AllScores!$F$2:$F$301))=0,"",SUMPRODUCT(MAX(((AllScores!$B$2:$B$301=$A7)*(AllScores!$E$2:$E$301=$B7)*(AllScores!$I$2:$I$301=1))*AllScores!$F$2:$F$301)))),"") | D7: {=IF($C7="","",IFERROR(INDEX(AllScores!$C$2:$C$301,SUMPRODUCT(((AllScores!$B$2:$B$301=$A7)*(AllScores!$E$2:$E$301=$B7)*(AllScores!$I$2:$I$301=1))*(AllScores!$F$2:$F$301=$C7)*(ROW(AllScores!$F$2:$F$301)-1))),""))} | E7: {=IF($C7="","",IFERROR(INDEX(AllScores!$A$2:$A$301,SUMPRODUCT(((AllScores!$B$2:$B$301=$A7)*(AllScores!$E$2:$E$301=$B7)*(AllScores!$I$2:$I$301=1))*(AllScores!$F$2:$F$301=$C7)*(ROW(AllScores!$A$2:$A$301)-1))),""))} | F7: =IFERROR(IF(SUMPRODUCT((AllScores!$B$2:$B$301=$A7)*(AllScores!$E$2:$E$301=$B7)*(AllScores!$I$2:$I$301=1))=0,"",IF(SUMPRODUCT(MAX(((AllScores!$B$2:$B$301=$A7)*(AllScores!$E$2:$E$301=$B7)*(AllScores!$I$2:$I$301=1))*AllScores!$G$2:$G$301))=0,"",SUMPRODUCT(MAX(((AllScores!$B$2:$B$301=$A7)*(AllScores!$E$2:$E$301=$B7)*(AllScores!$I$2:$I$301=1))*AllScores!$G$2:$G$301)))),"") | G7: {=IF($F7="","",IFERROR(INDEX(AllScores!$C$2:$C$301,SUMPRODUCT(((AllScores!$B$2:$B$301=$A7)*(AllScores!$E$2:$E$301=$B7)*(AllScores!$I$2:$I$301=1))*(AllScores!$G$2:$G$301=$F7)*(ROW(AllScores!$G$2:$G$301)-1))),""))} | H7: {=IF($F7="","",IFERROR(INDEX(AllScores!$A$2:$A$301,SUMPRODUCT(((AllScores!$B$2:$B$301=$A7)*(AllScores!$E$2:$E$301=$B7)*(AllScores!$I$2:$I$301=1))*(AllScores!$G$2:$G$301=$F7)*(ROW(AllScores!$A$2:$A$301)-1))),""))}
A8: prone_50m | B8: ladies | C8: =IFERROR(IF(SUMPRODUCT((AllScores!$B$2:$B$301=$A8)*(AllScores!$E$2:$E$301=$B8)*(AllScores!$I$2:$I$301=1))=0,"",IF(SUMPRODUCT(MAX(((AllScores!$B$2:$B$301=$A8)*(AllScores!$E$2:$E$301=$B8)*(AllScores!$I$2:$I$301=1))*AllScores!$F$2:$F$301))=0,"",SUMPRODUCT(MAX(((AllScores!$B$2:$B$301=$A8)*(AllScores!$E$2:$E$301=$B8)*(AllScores!$I$2:$I$301=1))*AllScores!$F$2:$F$301)))),"") | D8: {=IF($C8="","",IFERROR(INDEX(AllScores!$C$2:$C$301,SUMPRODUCT(((AllScores!$B$2:$B$301=$A8)*(AllScores!$E$2:$E$301=$B8)*(AllScores!$I$2:$I$301=1))*(AllScores!$F$2:$F$301=$C8)*(ROW(AllScores!$F$2:$F$301)-1))),""))} | E8: {=IF($C8="","",IFERROR(INDEX(AllScores!$A$2:$A$301,SUMPRODUCT(((AllScores!$B$2:$B$301=$A8)*(AllScores!$E$2:$E$301=$B8)*(AllScores!$I$2:$I$301=1))*(AllScores!$F$2:$F$301=$C8)*(ROW(AllScores!$A$2:$A$301)-1))),""))} | F8: =IFERROR(IF(SUMPRODUCT((AllScores!$B$2:$B$301=$A8)*(AllScores!$E$2:$E$301=$B8)*(AllScores!$I$2:$I$301=1))=0,"",IF(SUMPRODUCT(MAX(((AllScores!$B$2:$B$301=$A8)*(AllScores!$E$2:$E$301=$B8)*(AllScores!$I$2:$I$301=1))*AllScores!$G$2:$G$301))=0,"",SUMPRODUCT(MAX(((AllScores!$B$2:$B$301=$A8)*(AllScores!$E$2:$E$301=$B8)*(AllScores!$I$2:$I$301=1))*AllScores!$G$2:$G$301)))),"") | G8: {=IF($F8="","",IFERROR(INDEX(AllScores!$C$2:$C$301,SUMPRODUCT(((AllScores!$B$2:$B$301=$A8)*(AllScores!$E$2:$E$301=$B8)*(AllScores!$I$2:$I$301=1))*(AllScores!$G$2:$G$301=$F8)*(ROW(AllScores!$G$2:$G$301)-1))),""))} | H8: {=IF($F8="","",IFERROR(INDEX(AllScores!$A$2:$A$301,SUMPRODUCT(((AllScores!$B$2:$B$301=$A8)*(AllScores!$E$2:$E$301=$B8)*(AllScores!$I$2:$I$301=1))*(AllScores!$G$2:$G$301=$F8)*(ROW(AllScores!$A$2:$A$301)-1))),""))}
A9: fclass_open | B9: open | C9: =IFERROR(IF(SUMPRODUCT((AllScores!$B$2:$B$301=$A9)*(AllScores!$E$2:$E$301=$B9)*(AllScores!$I$2:$I$301=1))=0,"",IF(SUMPRODUCT(MAX(((AllScores!$B$2:$B$301=$A9)*(AllScores!$E$2:$E$301=$B9)*(AllScores!$I$2:$I$301=1))*AllScores!$F$2:$F$301))=0,"",SUMPRODUCT(MAX(((AllScores!$B$2:$B$301=$A9)*(AllScores!$E$2:$E$301=$B9)*(AllScores!$I$2:$I$301=1))*AllScores!$F$2:$F$301)))),"") | D9: {=IF($C9="","",IFERROR(INDEX(AllScores!$C$2:$C$301,SUMPRODUCT(((AllScores!$B$2:$B$301=$A9)*(AllScores!$E$2:$E$301=$B9)*(AllScores!$I$2:$I$301=1))*(AllScores!$F$2:$F$301=$C9)*(ROW(AllScores!$F$2:$F$301)-1))),""))} | E9: {=IF($C9="","",IFERROR(INDEX(AllScores!$A$2:$A$301,SUMPRODUCT(((AllScores!$B$2:$B$301=$A9)*(AllScores!$E$2:$E$301=$B9)*(AllScores!$I$2:$I$301=1))*(AllScores!$F$2:$F$301=$C9)*(ROW(AllScores!$A$2:$A$301)-1))),""))} | F9: =IFERROR(IF(SUMPRODUCT((AllScores!$B$2:$B$301=$A9)*(AllScores!$E$2:$E$301=$B9)*(AllScores!$I$2:$I$301=1))=0,"",IF(SUMPRODUCT(MAX(((AllScores!$B$2:$B$301=$A9)*(AllScores!$E$2:$E$301=$B9)*(AllScores!$I$2:$I$301=1))*AllScores!$G$2:$G$301))=0,"",SUMPRODUCT(MAX(((AllScores!$B$2:$B$301=$A9)*(AllScores!$E$2:$E$301=$B9)*(AllScores!$I$2:$I$301=1))*AllScores!$G$2:$G$301)))),"") | G9: {=IF($F9="","",IFERROR(INDEX(AllScores!$C$2:$C$301,SUMPRODUCT(((AllScores!$B$2:$B$301=$A9)*(AllScores!$E$2:$E$301=$B9)*(AllScores!$I$2:$I$301=1))*(AllScores!$G$2:$G$301=$F9)*(ROW(AllScores!$G$2:$G$301)-1))),""))} | H9: {=IF($F9="","",IFERROR(INDEX(AllScores!$A$2:$A$301,SUMPRODUCT(((AllScores!$B$2:$B$301=$A9)*(AllScores!$E$2:$E$301=$B9)*(AllScores!$I$2:$I$301=1))*(AllScores!$G$2:$G$301=$F9)*(ROW(AllScores!$A$2:$A$301)-1))),""))}
A10: fclass_open | B10: junior | C10: =IFERROR(IF(SUMPRODUCT((AllScores!$B$2:$B$301=$A10)*(AllScores!$E$2:$E$301=$B10)*(AllScores!$I$2:$I$301=1))=0,"",IF(SUMPRODUCT(MAX(((AllScores!$B$2:$B$301=$A10)*(AllScores!$E$2:$E$301=$B10)*(AllScores!$I$2:$I$301=1))*AllScores!$F$2:$F$301))=0,"",SUMPRODUCT(MAX(((AllScores!$B$2:$B$301=$A10)*(AllScores!$E$2:$E$301=$B10)*(AllScores!$I$2:$I$301=1))*AllScores!$F$2:$F$301)))),"") | D10: {=IF($C10="","",IFERROR(INDEX(AllScores!$C$2:$C$301,SUMPRODUCT(((AllScores!$B$2:$B$301=$A10)*(AllScores!$E$2:$E$301=$B10)*(AllScores!$I$2:$I$301=1))*(AllScores!$F$2:$F$301=$C10)*(ROW(AllScores!$F$2:$F$301)-1))),""))} | E10: {=IF($C10="","",IFERROR(INDEX(AllScores!$A$2:$A$301,SUMPRODUCT(((AllScores!$B$2:$B$301=$A10)*(AllScores!$E$2:$E$301=$B10)*(AllScores!$I$2:$I$301=1))*(AllScores!$F$2:$F$301=$C10)*(ROW(AllScores!$A$2:$A$301)-1))),""))} | F10: =IFERROR(IF(SUMPRODUCT((AllScores!$B$2:$B$301=$A10)*(AllScores!$E$2:$E$301=$B10)*(AllScores!$I$2:$I$301=1))=0,"",IF(SUMPRODUCT(MAX(((AllScores!$B$2:$B$301=$A10)*(AllScores!$E$2:$E$301=$B10)*(AllScores!$I$2:$I$301=1))*AllScores!$G$2:$G$301))=0,"",SUMPRODUCT(MAX(((AllScores!$B$2:$B$301=$A10)*(AllScores!$E$2:$E$301=$B10)*(AllScores!$I$2:$I$301=1))*AllScores!$G$2:$G$301)))),"") | G10: {=IF($F10="","",IFERROR(INDEX(AllScores!$C$2:$C$301,SUMPRODUCT(((AllScores!$B$2:$B$301=$A10)*(AllScores!$E$2:$E$301=$B10)*(AllScores!$I$2:$I$301=1))*(AllScores!$G$2:$G$301=$F10)*(ROW(AllScores!$G$2:$G$301)-1))),""))} | H10: {=IF($F10="","",IFERROR(INDEX(AllScores!$A$2:$A$301,SUMPRODUCT(((AllScores!$B$2:$B$301=$A10)*(AllScores!$E$2:$E$301=$B10)*(AllScores!$I$2:$I$301=1))*(AllScores!$G$2:$G$301=$F10)*(ROW(AllScores!$A$2:$A$301)-1))),""))}
A11: fclass_open | B11: veteran | C11: =IFERROR(IF(SUMPRODUCT((AllScores!$B$2:$B$301=$A11)*(AllScores!$E$2:$E$301=$B11)*(AllScores!$I$2:$I$301=1))=0,"",IF(SUMPRODUCT(MAX(((AllScores!$B$2:$B$301=$A11)*(AllScores!$E$2:$E$301=$B11)*(AllScores!$I$2:$I$301=1))*AllScores!$F$2:$F$301))=0,"",SUMPRODUCT(MAX(((AllScores!$B$2:$B$301=$A11)*(AllScores!$E$2:$E$301=$B11)*(AllScores!$I$2:$I$301=1))*AllScores!$F$2:$F$301)))),"") | D11: {=IF($C11="","",IFERROR(INDEX(AllScores!$C$2:$C$301,SUMPRODUCT(((AllScores!$B$2:$B$301=$A11)*(AllScores!$E$2:$E$301=$B11)*(AllScores!$I$2:$I$301=1))*(AllScores!$F$2:$F$301=$C11)*(ROW(AllScores!$F$2:$F$301)-1))),""))} | E11: {=IF($C11="","",IFERROR(INDEX(AllScores!$A$2:$A$301,SUMPRODUCT(((AllScores!$B$2:$B$301=$A11)*(AllScores!$E$2:$E$301=$B11)*(AllScores!$I$2:$I$301=1))*(AllScores!$F$2:$F$301=$C11)*(ROW(AllScores!$A$2:$A$301)-1))),""))} | F11: =IFERROR(IF(SUMPRODUCT((AllScores!$B$2:$B$301=$A11)*(AllScores!$E$2:$E$301=$B11)*(AllScores!$I$2:$I$301=1))=0,"",IF(SUMPRODUCT(MAX(((AllScores!$B$2:$B$301=$A11)*(AllScores!$E$2:$E$301=$B11)*(AllScores!$I$2:$I$301=1))*AllScores!$G$2:$G$301))=0,"",SUMPRODUCT(MAX(((AllScores!$B$2:$B$301=$A11)*(AllScores!$E$2:$E$301=$B11)*(AllScores!$I$2:$I$301=1))*AllScores!$G$2:$G$301)))),"") | G11: {=IF($F11="","",IFERROR(INDEX(AllScores!$C$2:$C$301,SUMPRODUCT(((AllScores!$B$2:$B$301=$A11)*(AllScores!$E$2:$E$301=$B11)*(AllScores!$I$2:$I$301=1))*(AllScores!$G$2:$G$301=$F11)*(ROW(AllScores!$G$2:$G$301)-1))),""))} | H11: {=IF($F11="","",IFERROR(INDEX(AllScores!$A$2:$A$301,SUMPRODUCT(((AllScores!$B$2:$B$301=$A11)*(AllScores!$E$2:$E$301=$B11)*(AllScores!$I$2:$I$301=1))*(AllScores!$G$2:$G$301=$F11)*(ROW(AllScores!$A$2:$A$301)-1))),""))}
A12: fclass_open | B12: ladies | C12: =IFERROR(IF(SUMPRODUCT((AllScores!$B$2:$B$301=$A12)*(AllScores!$E$2:$E$301=$B12)*(AllScores!$I$2:$I$301=1))=0,"",IF(SUMPRODUCT(MAX(((AllScores!$B$2:$B$301=$A12)*(AllScores!$E$2:$E$301=$B12)*(AllScores!$I$2:$I$301=1))*AllScores!$F$2:$F$301))=0,"",SUMPRODUCT(MAX(((AllScores!$B$2:$B$301=$A12)*(AllScores!$E$2:$E$301=$B12)*(AllScores!$I$2:$I$301=1))*AllScores!$F$2:$F$301)))),"") | D12: {=IF($C12="","",IFERROR(INDEX(AllScores!$C$2:$C$301,SUMPRODUCT(((AllScores!$B$2:$B$301=$A12)*(AllScores!$E$2:$E$301=$B12)*(AllScores!$I$2:$I$301=1))*(AllScores!$F$2:$F$301=$C12)*(ROW(AllScores!$F$2:$F$301)-1))),""))} | E12: {=IF($C12="","",IFERROR(INDEX(AllScores!$A$2:$A$301,SUMPRODUCT(((AllScores!$B$2:$B$301=$A12)*(AllScores!$E$2:$E$301=$B12)*(AllScores!$I$2:$I$301=1))*(AllScores!$F$2:$F$301=$C12)*(ROW(AllScores!$A$2:$A$301)-1))),""))} | F12: =IFERROR(IF(SUMPRODUCT((AllScores!$B$2:$B$301=$A12)*(AllScores!$E$2:$E$301=$B12)*(AllScores!$I$2:$I$301=1))=0,"",IF(SUMPRODUCT(MAX(((AllScores!$B$2:$B$301=$A12)*(AllScores!$E$2:$E$301=$B12)*(AllScores!$I$2:$I$301=1))*AllScores!$G$2:$G$301))=0,"",SUMPRODUCT(MAX(((AllScores!$B$2:$B$301=$A12)*(AllScores!$E$2:$E$301=$B12)*(AllScores!$I$2:$I$301=1))*AllScores!$G$2:$G$301)))),"") | G12: {=IF($F12="","",IFERROR(INDEX(AllScores!$C$2:$C$301,SUMPRODUCT(((AllScores!$B$2:$B$301=$A12)*(AllScores!$E$2:$E$301=$B12)*(AllScores!$I$2:$I$301=1))*(AllScores!$G$2:$G$301=$F12)*(ROW(AllScores!$G$2:$G$301)-1))),""))} | H12: {=IF($F12="","",IFERROR(INDEX(AllScores!$A$2:$A$301,SUMPRODUCT(((AllScores!$B$2:$B$301=$A12)*(AllScores!$E$2:$E$301=$B12)*(AllScores!$I$2:$I$301=1))*(AllScores!$G$2:$G$301=$F12)*(ROW(AllScores!$A$2:$A$301)-1))),""))}
A13: fclass_tr | B13: open | C13: =IFERROR(IF(SUMPRODUCT((AllScores!$B$2:$B$301=$A13)*(AllScores!$E$2:$E$301=$B13)*(AllScores!$I$2:$I$301=1))=0,"",IF(SUMPRODUCT(MAX(((AllScores!$B$2:$B$301=$A13)*(AllScores!$E$2:$E$301=$B13)*(AllScores!$I$2:$I$301=1))*AllScores!$F$2:$F$301))=0,"",SUMPRODUCT(MAX(((AllScores!$B$2:$B$301=$A13)*(AllScores!$E$2:$E$301=$B13)*(AllScores!$I$2:$I$301=1))*AllScores!$F$2:$F$301)))),"") | D13: {=IF($C13="","",IFERROR(INDEX(AllScores!$C$2:$C$301,SUMPRODUCT(((AllScores!$B$2:$B$301=$A13)*(AllScores!$E$2:$E$301=$B13)*(AllScores!$I$2:$I$301=1))*(AllScores!$F$2:$F$301=$C13)*(ROW(AllScores!$F$2:$F$301)-1))),""))} | E13: {=IF($C13="","",IFERROR(INDEX(AllScores!$A$2:$A$301,SUMPRODUCT(((AllScores!$B$2:$B$301=$A13)*(AllScores!$E$2:$E$301=$B13)*(AllScores!$I$2:$I$301=1))*(AllScores!$F$2:$F$301=$C13)*(ROW(AllScores!$A$2:$A$301)-1))),""))} | F13: =IFERROR(IF(SUMPRODUCT((AllScores!$B$2:$B$301=$A13)*(AllScores!$E$2:$E$301=$B13)*(AllScores!$I$2:$I$301=1))=0,"",IF(SUMPRODUCT(MAX(((AllScores!$B$2:$B$301=$A13)*(AllScores!$E$2:$E$301=$B13)*(AllScores!$I$2:$I$301=1))*AllScores!$G$2:$G$301))=0,"",SUMPRODUCT(MAX(((AllScores!$B$2:$B$301=$A13)*(AllScores!$E$2:$E$301=$B13)*(AllScores!$I$2:$I$301=1))*AllScores!$G$2:$G$301)))),"") | G13: {=IF($F13="","",IFERROR(INDEX(AllScores!$C$2:$C$301,SUMPRODUCT(((AllScores!$B$2:$B$301=$A13)*(AllScores!$E$2:$E$301=$B13)*(AllScores!$I$2:$I$301=1))*(AllScores!$G$2:$G$301=$F13)*(ROW(AllScores!$G$2:$G$301)-1))),""))} | H13: {=IF($F13="","",IFERROR(INDEX(AllScores!$A$2:$A$301,SUMPRODUCT(((AllScores!$B$2:$B$301=$A13)*(AllScores!$E$2:$E$301=$B13)*(AllScores!$I$2:$I$301=1))*(AllScores!$G$2:$G$301=$F13)*(ROW(AllScores!$A$2:$A$301)-1))),""))}
A14: fclass_tr | B14: junior | C14: =IFERROR(IF(SUMPRODUCT((AllScores!$B$2:$B$301=$A14)*(AllScores!$E$2:$E$301=$B14)*(AllScores!$I$2:$I$301=1))=0,"",IF(SUMPRODUCT(MAX(((AllScores!$B$2:$B$301=$A14)*(AllScores!$E$2:$E$301=$B14)*(AllScores!$I$2:$I$301=1))*AllScores!$F$2:$F$301))=0,"",SUMPRODUCT(MAX(((AllScores!$B$2:$B$301=$A14)*(AllScores!$E$2:$E$301=$B14)*(AllScores!$I$2:$I$301=1))*AllScores!$F$2:$F$301)))),"") | D14: {=IF($C14="","",IFERROR(INDEX(AllScores!$C$2:$C$301,SUMPRODUCT(((AllScores!$B$2:$B$301=$A14)*(AllScores!$E$2:$E$301=$B14)*(AllScores!$I$2:$I$301=1))*(AllScores!$F$2:$F$301=$C14)*(ROW(AllScores!$F$2:$F$301)-1))),""))} | E14: {=IF($C14="","",IFERROR(INDEX(AllScores!$A$2:$A$301,SUMPRODUCT(((AllScores!$B$2:$B$301=$A14)*(AllScores!$E$2:$E$301=$B14)*(AllScores!$I$2:$I$301=1))*(AllScores!$F$2:$F$301=$C14)*(ROW(AllScores!$A$2:$A$301)-1))),""))} | F14: =IFERROR(IF(SUMPRODUCT((AllScores!$B$2:$B$301=$A14)*(AllScores!$E$2:$E$301=$B14)*(AllScores!$I$2:$I$301=1))=0,"",IF(SUMPRODUCT(MAX(((AllScores!$B$2:$B$301=$A14)*(AllScores!$E$2:$E$301=$B14)*(AllScores!$I$2:$I$301=1))*AllScores!$G$2:$G$301))=0,"",SUMPRODUCT(MAX(((AllScores!$B$2:$B$301=$A14)*(AllScores!$E$2:$E$301=$B14)*(AllScores!$I$2:$I$301=1))*AllScores!$G$2:$G$301)))),"") | G14: {=IF($F14="","",IFERROR(INDEX(AllScores!$C$2:$C$301,SUMPRODUCT(((AllScores!$B$2:$B$301=$A14)*(AllScores!$E$2:$E$301=$B14)*(AllScores!$I$2:$I$301=1))*(AllScores!$G$2:$G$301=$F14)*(ROW(AllScores!$G$2:$G$301)-1))),""))} | H14: {=IF($F14="","",IFERROR(INDEX(AllScores!$A$2:$A$301,SUMPRODUCT(((AllScores!$B$2:$B$301=$A14)*(AllScores!$E$2:$E$301=$B14)*(AllScores!$I$2:$I$301=1))*(AllScores!$G$2:$G$301=$F14)*(ROW(AllScores!$A$2:$A$301)-1))),""))}
A15: fclass_tr | B15: veteran | C15: =IFERROR(IF(SUMPRODUCT((AllScores!$B$2:$B$301=$A15)*(AllScores!$E$2:$E$301=$B15)*(AllScores!$I$2:$I$301=1))=0,"",IF(SUMPRODUCT(MAX(((AllScores!$B$2:$B$301=$A15)*(AllScores!$E$2:$E$301=$B15)*(AllScores!$I$2:$I$301=1))*AllScores!$F$2:$F$301))=0,"",SUMPRODUCT(MAX(((AllScores!$B$2:$B$301=$A15)*(AllScores!$E$2:$E$301=$B15)*(AllScores!$I$2:$I$301=1))*AllScores!$F$2:$F$301)))),"") | D15: {=IF($C15="","",IFERROR(INDEX(AllScores!$C$2:$C$301,SUMPRODUCT(((AllScores!$B$2:$B$301=$A15)*(AllScores!$E$2:$E$301=$B15)*(AllScores!$I$2:$I$301=1))*(AllScores!$F$2:$F$301=$C15)*(ROW(AllScores!$F$2:$F$301)-1))),""))} | E15: {=IF($C15="","",IFERROR(INDEX(AllScores!$A$2:$A$301,SUMPRODUCT(((AllScores!$B$2:$B$301=$A15)*(AllScores!$E$2:$E$301=$B15)*(AllScores!$I$2:$I$301=1))*(AllScores!$F$2:$F$301=$C15)*(ROW(AllScores!$A$2:$A$301)-1))),""))} | F15: =IFERROR(IF(SUMPRODUCT((AllScores!$B$2:$B$301=$A15)*(AllScores!$E$2:$E$301=$B15)*(AllScores!$I$2:$I$301=1))=0,"",IF(SUMPRODUCT(MAX(((AllScores!$B$2:$B$301=$A15)*(AllScores!$E$2:$E$301=$B15)*(AllScores!$I$2:$I$301=1))*AllScores!$G$2:$G$301))=0,"",SUMPRODUCT(MAX(((AllScores!$B$2:$B$301=$A15)*(AllScores!$E$2:$E$301=$B15)*(AllScores!$I$2:$I$301=1))*AllScores!$G$2:$G$301)))),"") | G15: {=IF($F15="","",IFERROR(INDEX(AllScores!$C$2:$C$301,SUMPRODUCT(((AllScores!$B$2:$B$301=$A15)*(AllScores!$E$2:$E$301=$B15)*(AllScores!$I$2:$I$301=1))*(AllScores!$G$2:$G$301=$F15)*(ROW(AllScores!$G$2:$G$301)-1))),""))} | H15: {=IF($F15="","",IFERROR(INDEX(AllScores!$A$2:$A$301,SUMPRODUCT(((AllScores!$B$2:$B$301=$A15)*(AllScores!$E$2:$E$301=$B15)*(AllScores!$I$2:$I$301=1))*(AllScores!$G$2:$G$301=$F15)*(ROW(AllScores!$A$2:$A$301)-1))),""))}
A16: fclass_tr | B16: ladies | C16: =IFERROR(IF(SUMPRODUCT((AllScores!$B$2:$B$301=$A16)*(AllScores!$E$2:$E$301=$B16)*(AllScores!$I$2:$I$301=1))=0,"",IF(SUMPRODUCT(MAX(((AllScores!$B$2:$B$301=$A16)*(AllScores!$E$2:$E$301=$B16)*(AllScores!$I$2:$I$301=1))*AllScores!$F$2:$F$301))=0,"",SUMPRODUCT(MAX(((AllScores!$B$2:$B$301=$A16)*(AllScores!$E$2:$E$301=$B16)*(AllScores!$I$2:$I$301=1))*AllScores!$F$2:$F$301)))),"") | D16: {=IF($C16="","",IFERROR(INDEX(AllScores!$C$2:$C$301,SUMPRODUCT(((AllScores!$B$2:$B$301=$A16)*(AllScores!$E$2:$E$301=$B16)*(AllScores!$I$2:$I$301=1))*(AllScores!$F$2:$F$301=$C16)*(ROW(AllScores!$F$2:$F$301)-1))),""))} | E16: {=IF($C16="","",IFERROR(INDEX(AllScores!$A$2:$A$301,SUMPRODUCT(((AllScores!$B$2:$B$301=$A16)*(AllScores!$E$2:$E$301=$B16)*(AllScores!$I$2:$I$301=1))*(AllScores!$F$2:$F$301=$C16)*(ROW(AllScores!$A$2:$A$301)-1))),""))} | F16: =IFERROR(IF(SUMPRODUCT((AllScores!$B$2:$B$301=$A16)*(AllScores!$E$2:$E$301=$B16)*(AllScores!$I$2:$I$301=1))=0,"",IF(SUMPRODUCT(MAX(((AllScores!$B$2:$B$301=$A16)*(AllScores!$E$2:$E$301=$B16)*(AllScores!$I$2:$I$301=1))*AllScores!$G$2:$G$301))=0,"",SUMPRODUCT(MAX(((AllScores!$B$2:$B$301=$A16)*(AllScores!$E$2:$E$301=$B16)*(AllScores!$I$2:$I$301=1))*AllScores!$G$2:$G$301)))),"") | G16: {=IF($F16="","",IFERROR(INDEX(AllScores!$C$2:$C$301,SUMPRODUCT(((AllScores!$B$2:$B$301=$A16)*(AllScores!$E$2:$E$301=$B16)*(AllScores!$I$2:$I$301=1))*(AllScores!$G$2:$G$301=$F16)*(ROW(AllScores!$G$2:$G$301)-1))),""))} | H16: {=IF($F16="","",IFERROR(INDEX(AllScores!$A$2:$A$301,SUMPRODUCT(((AllScores!$B$2:$B$301=$A16)*(AllScores!$E$2:$E$301=$B16)*(AllScores!$I$2:$I$301=1))*(AllScores!$G$2:$G$301=$F16)*(ROW(AllScores!$A$2:$A$301)-1))),""))}
... A20: three_position_50m | B20: ladies | C20: =IFERROR(IF(SUMPRODUCT((AllScores!$B$2:$B$301=$A20)*(AllScores!$E$2:$E$301=$B20)*(AllScores!$I$2:$I$301=1))=0,"",IF(SUMPRODUCT(MAX(((AllScores!$B$2:$B$301=$A20)*(AllScores!$E$2:$E$301=$B20)*(AllScores!$I$2:$I$301=1))*AllScores!$F$2:$F$301))=0,"",SUMPRODUCT(MAX(((AllScores!$B$2:$B$301=$A20)*(AllScores!$E$2:$E$301=$B20)*(AllScores!$I$2:$I$301=1))*AllScores!$F$2:$F$301)))),"") | D20: {=IF($C20="","",IFERROR(INDEX(AllScores!$C$2:$C$301,SUMPRODUCT(((AllScores!$B$2:$B$301=$A20)*(AllScores!$E$2:$E$301=$B20)*(AllScores!$I$2:$I$301=1))*(AllScores!$F$2:$F$301=$C20)*(ROW(AllScores!$F$2:$F$301)-1))),""))} | E20: {=IF($C20="","",IFERROR(INDEX(AllScores!$A$2:$A$301,SUMPRODUCT(((AllScores!$B$2:$B$301=$A20)*(AllScores!$E$2:$E$301=$B20)*(AllScores!$I$2:$I$301=1))*(AllScores!$F$2:$F$301=$C20)*(ROW(AllScores!$A$2:$A$301)-1))),""))} | F20: =IFERROR(IF(SUMPRODUCT((AllScores!$B$2:$B$301=$A20)*(AllScores!$E$2:$E$301=$B20)*(AllScores!$I$2:$I$301=1))=0,"",IF(SUMPRODUCT(MAX(((AllScores!$B$2:$B$301=$A20)*(AllScores!$E$2:$E$301=$B20)*(AllScores!$I$2:$I$301=1))*AllScores!$G$2:$G$301))=0,"",SUMPRODUCT(MAX(((AllScores!$B$2:$B$301=$A20)*(AllScores!$E$2:$E$301=$B20)*(AllScores!$I$2:$I$301=1))*AllScores!$G$2:$G$301)))),"") | G20: {=IF($F20="","",IFERROR(INDEX(AllScores!$C$2:$C$301,SUMPRODUCT(((AllScores!$B$2:$B$301=$A20)*(AllScores!$E$2:$E$301=$B20)*(AllScores!$I$2:$I$301=1))*(AllScores!$G$2:$G$301=$F20)*(ROW(AllScores!$G$2:$G$301)-1))),""))} | H20: {=IF($F20="","",IFERROR(INDEX(AllScores!$A$2:$A$301,SUMPRODUCT(((AllScores!$B$2:$B$301=$A20)*(AllScores!$E$2:$E$301=$B20)*(AllScores!$I$2:$I$301=1))*(AllScores!$G$2:$G$301=$F20)*(ROW(AllScores!$A$2:$A$301)-1))),""))}
A22: Holder/date shown are for the first matching best score. Records cover all valid entries in the workbook (status not required). Blank = no entry yet for that class.

Sheet Members
A1: Shooter Name | B1: Club | C1: Default Category | E1: Maintain your member roster here. Names listed here appear in the Shooter dropdowns on the score tabs. Guests can still be typed in freely.
A2: Arnold Prone | B2: Modderbee | C2: open
A3: Jane Member | B3: SATRF Club | C3: ladies
A4: Pieter van Wyk | B4: Pretoria RC | C4: open
A5: Sarah Naidoo | B5: SATRF Club | C5: ladies
A6: Johan Botha | B6: Bloem Marksmen | C6: veteran
A7: Thabo Mokoena | B7: Modderbee | C7: open
A8: Lerato Dlamini | B8: SATRF Club | C8: junior
A9: Willem Pretorius | B9: Pretoria RC | C9: veteran
A10: Anita Smit | B10: Cape Rifle Club | C10: ladies
A11: David Khumalo | B11: Modderbee | C11: open
A12: Riaan Steyn | B12: Bloem Marksmen | C12: open
A13: Mary Adams | B13: Cape Rifle Club | C13: veteran
... A16: Karen Joubert | B16: Cape Rifle Club | C16: ladies

Sheet Lookups
A1: Field | B1: Values
A2: Discipline | B2: prone_50m, fclass_open, fclass_tr, three_position_50m
A3: Category | B3: open, junior, veteran, ladies
A4: Status | B4: official, provisional
A5: Clubs | B5: Modderbee, SATRF Club, Pretoria RC, Bloem Marksmen, Cape Rifle Club

Sheet Dates
A1: 46023
A2: 46024
A3: 46025
A4: 46026
A5: 46027
A6: 46028
A7: 46029
A8: 46030
A9: 46031
A10: 46032
A11: 46033
A12: 46034
... A730: 46752

Sheet AllScores
A1: Date | B1: Discipline | C1: Shooter | D1: Club | E1: Category | F1: TotalDec | G1: TotalInt | H1: Year | I1: Valid
A2: ='Prone 50m'!A2 -> 2026-05-09 | B2: ='Prone 50m'!C2 -> prone_50m | C2: ='Prone 50m'!D2 -> Arnold Prone | D2: ='Prone 50m'!E2 -> Modderbee | E2: ='Prone 50m'!F2 -> open | F2: =IF('Prone 50m'!S2="",0,'Prone 50m'!S2) -> 600.4 | G2: =IF('Prone 50m'!T2="",0,'Prone 50m'!T2) -> 567 | H2: =IFERROR(YEAR('Prone 50m'!A2),"") -> 2026 | I2: =IF(AND('Prone 50m'!D2<>"",'Prone 50m'!S2<>""),1,0) -> 1
